<?xml version='1.0'?>

<robot name="shreyas_bot" xmlns:xacro="http://www.ros.org/wiki/xacro">
<xacro:include filename="$(find shreyas_bot)/urdf/shreyas_bot.gazebo" />
<xacro:include filename="$(find shreyas_bot)/urdf/shreyas_materials.xacro" />

  <link name="robot_footprint"></link>

  <joint name="robot_footprint_joint" type="fixed">
    <origin xyz="0 0 0" rpy="0 0 0" />
    <parent link="robot_footprint"/>
    <child link="chassis" />
  </joint>

  <!-- chassis link -->
  <link name='chassis'>
    <pose>0 0 0.1 0 0 0</pose>

    <inertial>
      <mass value="16.5"/>
      <origin xyz="0.0 0 0" rpy=" 0 0 0"/>
      <inertia
          ixx="0.11" ixy="0" ixz="0"
          iyy="0.11" iyz="0"
          izz="0.11"
      />
    </inertial>

    <collision name='collision'>
      <origin xyz="0 0 0" rpy=" 0 0 0"/> 
      <geometry>
        <box size=".44 .22 .11"/>
      </geometry>
    </collision>

    <visual name='chassis_visual'>
      <origin xyz="0 0 0" rpy=" 0 0 0"/>
      <geometry>
        <box size=".44 .22 .11"/>
      </geometry>
      <material name="blue"/>
    </visual>


    <collision name='back_caster_collision'>
      <origin xyz="-0.165 0 -0.055" rpy=" 0 0 0"/>
      <geometry>
        <sphere radius="0.055"/>
      </geometry>
      <surface>
        <friction>
          <ode>
            <mu>0</mu>
            <mu2>0</mu2>
            <slip1>1.0</slip1>
            <slip2>1.0</slip2>
          </ode>
        </friction>
      </surface>
    </collision>

    <visual name='back_caster_visual'>
      <origin xyz="-0.165 0 -0.055" rpy=" 0 0 0"/>
      <geometry>
        <sphere radius="0.055"/>
      </geometry>
    </visual>

    <collision name='front_caster_collision'>
      <origin xyz="0.165 0 -0.055" rpy=" 0 0 0"/>
      <geometry>
        <sphere radius="0.055"/>
      </geometry>
      <surface>
        <friction>
          <ode>
            <mu>0</mu>
            <mu2>0</mu2>
            <slip1>1.0</slip1>
            <slip2>1.0</slip2>
          </ode>
        </friction>
      </surface>
    </collision>

    <visual name='front_caster_visual'>
      <origin xyz="0.165 0 -0.055" rpy=" 0 0 0"/>
      <geometry>
        <sphere radius="0.055"/>
      </geometry>
    </visual>
  </link>

  <!-- left Wheel link -->
  <link name="left_wheel">
    <pose>0 0 0 0 1.5707 1.5707</pose>

    <inertial>
      <mass value="5.5"/>
      <origin xyz="0 0 0" rpy=" 0 1.5707 1.5707"/>
      <inertia
          ixx="0.1" ixy="0" ixz="0"
          iyy="0.1" iyz="0"
          izz="0.1"
      />
    </inertial>

    <collision name="collision">
      <origin xyz="0 0 0" rpy=" 0 1.5707 1.5707"/>
      <geometry>
        <cylinder length="0.055" radius="0.11"/>
      </geometry>
    </collision>
    
    <visual name="visual">
      <origin xyz="0 0 0" rpy=" 0 1.5707 1.5707"/>
      <geometry>
        <cylinder length="0.055" radius="0.11"/>
      </geometry>
      <material name="green"/>
    </visual>
  </link>

  <!-- right Wheel link -->
  <link name="right_wheel">
    <pose>0 0 0 0 -1.5707 1.5707</pose>

    <inertial>
      <mass value="5.5"/>
      <origin xyz="0 0 0" rpy=" 0 -1.5707 1.5707"/>
      <inertia
          ixx="0.1" ixy="0" ixz="0"
          iyy="0.1" iyz="0"
          izz="0.1"
      />
    </inertial>

    <collision name="collision">
      <origin xyz="0 0 0" rpy=" 0 -1.5707 1.5707"/>
      <geometry>
        <cylinder length="0.055" radius="0.11"/>
      </geometry>
    </collision>
    
    <visual name="visual">
      <origin xyz="0 0 0" rpy=" 0 -1.5707 1.5707"/>
      <geometry>
        <cylinder length="0.055" radius="0.11"/>
      </geometry>
      <material name="green"/>
    </visual>
  </link>

  <!-- camera link -->
  <link name='camera'>
    <pose>0 0 0 0 0 0</pose>

    <inertial>
      <mass value="0.1"/>
      <origin xyz="0.0 0 0" rpy=" 0 0 0"/>
      <inertia
          ixx="1e-6" ixy="0" ixz="0"
          iyy="1e-6" iyz="0"
          izz="1e-6"
      />
    </inertial>

    <collision name='collision'>
      <origin xyz="0 0 0" rpy=" 0 0 0"/> 
      <geometry>
        <box size=".05 .05 .05"/>
      </geometry>
    </collision>

    <visual name='chassis_visual'>
      <origin xyz="0 0 0" rpy=" 0 0 0"/>
      <geometry>
        <box size=".05 .05 .05"/>
      </geometry>
      <material name="red"/>
    </visual>
  </link>

  <!-- laser rangefinder link -->
  <link name='hokuyo'>
    <pose>0 0 0 0 0 0</pose>

    <inertial>
      <mass value="0.1"/>
      <origin xyz="0.0 0 0" rpy=" 0 0 0"/>
      <inertia
          ixx="1e-6" ixy="0" ixz="0"
          iyy="1e-6" iyz="0"
          izz="1e-6"
      />
    </inertial>

    <collision name='collision'>
      <origin xyz="0 0 0" rpy=" 0 0 0"/> 
      <geometry>
        <box size=".01 .01 .01"/>
      </geometry>
    </collision>

    <visual name='chassis_visual'>
      <origin xyz="0 0 0" rpy=" 0 0 0"/>
      <geometry>
        <mesh filename="package://shreyas_bot/meshes/hokuyo.dae"/>
      </geometry>
    </visual>
  </link>


  <!-- left wheel joint -->
  <joint type="continuous" name="left_wheel_hinge">
    <origin xyz="0 0.165 0" rpy="0 0 0"/>
    <child link="left_wheel"/>
    <parent link="chassis"/>
    <axis xyz="0 1 0" rpy="0 0 0"/>
    <limit effort="11000" velocity="1000"/>
    <joint_properties damping="1.0" friction="1.0"/>
  </joint>

  <!-- right wheel joint -->
  <joint type="continuous" name="right_wheel_hinge">
    <origin xyz="0 -0.165 0" rpy="0 0 0"/>
    <child link="right_wheel"/>
    <parent link="chassis"/>
    <axis xyz="0 1 0" rpy="0 0 0"/>
    <limit effort="11000" velocity="1000"/>
    <joint_properties damping="1.0" friction="1.0"/>
  </joint>

  <!-- camera joint -->
  <joint type="fixed" name="camera_joint">
    <origin xyz="0.22 0 0" rpy="0 0 0"/>
    <child link="camera"/>
    <parent link="chassis"/>
    <axis xyz="0 1 0" rpy="0 0 0"/>
    <limit effort="10000" velocity="1000"/>
    <joint_properties damping="1.0" friction="1.0"/>
  </joint>

  <!-- laser rangefinder joint -->
  <joint type="fixed" name="hokuyo_joint">
    <origin xyz="0.165 0 0.07" rpy="0 0 0"/>
    <child link="hokuyo"/>
    <parent link="chassis"/>
    <axis xyz="0 1 0" rpy="0 0 0"/>
    <limit effort="10000" velocity="1000"/>
    <joint_properties damping="1.0" friction="1.0"/>
  </joint>

</robot>